<?xml version="1.0"?>
<robot name="amr" xmlns:xacro="http://ros.org/wiki/xacro">

  <xacro:property name="body_length" value="0.6"/>
  <xacro:property name="body_width" value="0.4"/>
  <xacro:property name="body_height" value="0.1"/>
  <xacro:property name="wheel_length" value="0.06"/>
  <xacro:property name="wheel_radius" value="0.08"/>
  <xacro:property name="x_off" value="0.05"/>
  <xacro:property name="z_off" value="0.015"/>

  <xacro:macro name="wheel" params="name fb rl">
    <!-- wheel macro -->
    <link name="${name}_wheel">
      <visual>
        <geometry>
          <cylinder radius="${wheel_radius}" length="${wheel_length}"/>
        </geometry>
        <origin rpy="${pi/2} 0 0"/>
        <material name="orange">
          <color rgba="${255/255} ${108/255} ${10/255} 1"/>
        </material>
      </visual>
      <collision>
        <geometry>
          <cylinder radius="${wheel_radius}" length="${wheel_length}"/>
        </geometry>
        <origin rpy="${pi/2} 0 0"/>
      </collision>
      <xacro:cylinder_inertia m="1.0" r="${wheel_radius}" h="${wheel_length}"/>
    </link>
    <joint name="${name}_to_base" type="continuous">
      <axis xyz="0 1 0"/>
      <parent link="base_footprint"/>
      <child link="${name}_wheel"/>
      <origin xyz="${fb * (body_length/2 - x_off)} ${-rl * (body_width/2 + wheel_length/2)} ${-z_off}" rpy="0 0 0"/>
    </joint>
  </xacro:macro>

  <xacro:macro name="box_inertia" params="m l b h">
    <inertial>
      <mass value="${m}"/>
      <inertia ixx="${m/12 * (b*b + h*h)}" iyy="${m/12 * (l*l + h*h)}" izz="${m/12 * (l*l + b*b)}" ixy="0.0" iyz="0.0" ixz="0.0"/>
    </inertial>
  </xacro:macro>

  <xacro:macro name="cylinder_inertia" params="m r h">
    <inertial>
      <origin rpy="${pi/2} 0 0"/>
      <mass value="${m}"/>
      <inertia ixx="${m/12 * (3*r*r + h*h)}" iyy="${m/12 * (3*r*r + h*h)}" izz="${m/2 * r*r}" ixy="0.0" iyz="0.0" ixz="0.0"/>
    </inertial>
  </xacro:macro>

  <!-- base link -->
  <link name="base_link"/>

  <!-- base footprint -->
  <link name="base_footprint">
    <visual>
      <geometry>
        <box size="${body_length} ${body_width} ${body_height}"/>
      </geometry>
      <!-- <origin xyz="0 0 0"/> -->
      <material name="white">
        <color rgba="1 1 1 0.95"/>
      </material>
    </visual>
    <collision>
      <geometry>
        <box size="${body_length} ${body_width} ${body_height}"/>
      </geometry>
    </collision>
    <xacro:box_inertia m="10" l="${body_length}" b="${body_width}" h="${body_height}"/>
  </link>

  <joint name="base_joint" type="fixed">
    <parent link="base_link"/>
    <child link="base_footprint"/>
    <origin xyz="0 0 ${wheel_radius + z_off}"/>
  </joint>


  <!-- defining all wheels -->
  <xacro:wheel name="front_right" fb="1" rl="1"/>
  <xacro:wheel name="front_left" fb="1" rl="-1"/>
  <xacro:wheel name="back_right" fb="-1" rl="1"/>
  <xacro:wheel name="back_left" fb="-1" rl="-1"/>

  <!-- <link name="wheel">
    <visual>
      <geometry>
        <cylinder radius="${wheel_radius}" length="${wheel_length}"/>
      </geometry>
      <origin xyz="0 0 0" rpy="${pi/2} 0 0"/>
    </visual>
  </link>

  <joint name="wheel_to_base" type="continuous">
    <axis xyz="0 1 0"/>
    <parent link="base_footprint"/>
    <child link="wheel"/>
    <origin xyz="${body_length/2 - x_off} ${body_width/2 + wheel_length/2} -${z_off}"/>
  </joint> -->

</robot>
